<?xml version='1.0' encoding='utf-8'?>
<robot name="panda_sensor">

    <link name="link0">
      <inertial>
        <mass value="2.92" />
        <origin xyz="-0.025566 -2.88e-05 0.057332" rpy="0 0 0" />
        <inertia ixx="0.00782229414331" ixy="-1.56191622996e-05" ixz="-0.00126005738123" iyy="0.0109027971813" iyz="1.08233858202e-05" izz="0.0102355503949" />
      </inertial>
      <visual>
        <geometry>
          <mesh filename="../../../robot_models/Panda/meshes/link0.obj"/>
        </geometry>
      </visual>
<!--       <collision>
        <geometry>
          <mesh filename="../../../robot_models/Panda/meshes/link0.obj"/>
        </geometry>
      </collision> -->
    </link>
    <link name="link1">
      <inertial>
        <mass value="2.74" />
        <origin xyz="0 -0.0324958 -0.0675818" rpy="0 0 0" />
        <inertia ixx="0.0180416958283" ixy="0.0" ixz="0.0" iyy="0.0159136071891" iyz="0.0046758424612" izz="0.00620690827127" />
      </inertial>
      <visual>
        <geometry>
          <mesh filename="../../../robot_models/Panda/meshes/link1.obj"/>
        </geometry>
      </visual>
      <!-- <collision>
        <geometry>
          <mesh filename="../../../robot_models/Panda/meshes/link1.obj"/>
        </geometry>
      </collision> -->
    </link>
    <link name="link2">
       <inertial>
        <mass value="2.74" />
        <origin xyz="0 -0.06861 0.0322285" rpy="0 0 0" />
        <inertia ixx="0.0182856182281" ixy="0.0" ixz="0.0" iyy="0.00621358421175" iyz="-0.00472844221905" izz="0.0161514346309" />
      </inertial>
      <visual>
        <geometry>
          <mesh filename="../../../robot_models/Panda/meshes/link2.obj"/>
        </geometry>
      </visual>
      <!-- <collision>
        <geometry>
          <mesh filename="../../../robot_models/Panda/meshes/link2.obj"/>
        </geometry>
      </collision> -->
    </link>
    <link name="link3">
     <inertial>
        <mass value="2.38" />
        <origin xyz="0.0469893 0.0316374 -0.031704" rpy="0 0 0" />
        <inertia ixx="0.00771376630908" ixy="-0.00248490625138" ixz="-0.00332147581033" iyy="0.00989108008727" iyz="-0.00217796151484" izz="0.00811723558464" />
      </inertial>
      <visual>
        <geometry>
          <mesh filename="../../../robot_models/Panda/meshes/link3.obj"/>
        </geometry>
      </visual>
      <!-- <collision>
        <geometry>
          <mesh filename="../../../robot_models/Panda/meshes/link3.obj"/>
        </geometry>
      </collision> -->
    </link>
    <link name="link4">
      <inertial>
        <mass value="2.38" />
        <origin xyz="-0.0360446 0.0336853 0.031882" rpy="0 0 0" />
        <inertia ixx="0.00799663881132" ixy="0.00347095570217" ixz="-0.00241222942995" iyy="0.00825390705278" iyz="0.00235774044121" izz="0.0102515004345" />
      </inertial>
      <visual>
        <geometry>
          <mesh filename="../../../robot_models/Panda/meshes/link4.obj"/>
        </geometry>
      </visual>
      <!-- <collision>
        <geometry>
          <mesh filename="../../../robot_models/Panda/meshes/link4.obj"/>
        </geometry>
      </collision> -->
    </link>
    <link name="link5">
        <inertial>
        <mass value="2.74" />
        <origin xyz="0 0.0610427 -0.104176" rpy="0 0 0" />
        <inertia ixx="0.030371374513" ixy="6.50283587108e-07" ixz="-1.05129179916e-05" iyy="0.0288752887402" iyz="-0.00775653445787" izz="0.00444134056164" />
      </inertial>
      <visual>
        <geometry>
          <mesh filename="../../../robot_models/Panda/meshes/link5.obj"/>
        </geometry>
      </visual>
      <!-- <collision>
        <geometry>
          <mesh filename="../../../robot_models/Panda/meshes/link5.obj"/>
        </geometry>
      </collision> -->
    </link>
    <link name="link6">
      <inertial>
        <mass value="1.55" />
        <origin xyz="0.0510509 0.009108 0.0106343" rpy="0 0 0" />
        <inertia ixx="0.00303336450376" ixy="-0.000437276865508" ixz="0.000629257294877" iyy="0.00404479911567" iyz="0.000130472021025" izz="0.00558234286039" />
      </inertial>
      <visual>
        <geometry>
          <mesh filename="../../../robot_models/Panda/meshes/link6.obj"/>
        </geometry>
      </visual>
      <!-- <collision>
        <geometry>
          <mesh filename="../../../robot_models/Panda/meshes/link6.obj"/>
        </geometry>
      </collision> -->
    </link>
    <link name="link7">
       <inertial>
        <mass value="0.54" />
        <origin xyz="0.0109695 0.0107965 0.0650411" rpy="0 0 0" />
        <inertia ixx="0.000888868887021" ixy="-0.00012239074652" ixz="3.98699829666e-05" iyy="0.000888001373233" iyz="-9.33825115206e-05" izz="0.0007176834609" />
      </inertial>
\
 <!--      <inertial>
        <origin xyz="0.007 0 0.1" rpy="0 -0 0" />
        <mass value="1.808" />
        <inertia ixx="0.4" iyy="0.4" izz="0.4" ixy="0" ixz="0" iyz="0" />
      </inertial> -->
      <visual>
        <origin xyz="0 0 0" rpy="0 0 0" />
        <geometry>
          <mesh filename="../../../robot_models/Panda/meshes/link7.obj"/>
        </geometry>
      </visual>
      <!-- <collision>
        <geometry>
          <mesh filename="../../../robot_models/Panda/meshes/link7.obj"/>
        </geometry>
      </collision> -->
</link>
<link name="opto_link_1">
  <inertial>
    <mass value="0.033333" />
    <origin xyz="0.0 0.0 0.0029166" rpy="0 0 0" />
    <inertia ixx="0.0000103029" ixy="0.0" ixz="0.0" iyy="0.0000103029" iyz="0.0" izz="0.0000204167" />
  </inertial>
  <visual>
      <geometry>
        <cylinder length="0.00583333" radius="0.035"/>
      </geometry>
  </visual>
     <collision>
    <origin xyz="0 0 0" rpy="0 0 0"/>
    <geometry>
      <cylinder length="0.00583333" radius="0.035"/>
    </geometry>
  </collision> 
</link>
<link name="opto_link_2">
  <inertial>
    <mass value="0.033333" />
    <origin xyz="0.0 0.0 0.0029166" rpy="0 0 0" />
    <inertia ixx="0.0000103029" ixy="0.0" ixz="0.0" iyy="0.0000103029" iyz="0.0" izz="0.0000204167" />
  </inertial>
      <visual>
      <geometry>
        <cylinder length="0.00583333" radius="0.035"/>
      </geometry>
  </visual>
     <collision>
    <origin xyz="0 0 0" rpy="0 0 0"/>
    <geometry>
      <cylinder length="0.00583333" radius="0.035"/>
    </geometry>
  </collision> 
</link>
<link name="opto_link_3">
  <inertial>
    <mass value="0.033333" />
    <origin xyz="0.0 0.0 0.0029166" rpy="0 0 0" />
    <inertia ixx="0.0000103029" ixy="0.0" ixz="0.0" iyy="0.0000103029" iyz="0.0" izz="0.0000204167" />
  </inertial>
    <visual>
      <geometry>
        <cylinder length="0.00583333" radius="0.035"/>
      </geometry>
  </visual>
     <collision>
    <origin xyz="0 0 0" rpy="0 0 0"/>
    <geometry>
      <cylinder length="0.00583333" radius="0.035"/>
    </geometry>
  </collision> 
</link>
<link name="opto_link_4">
  <inertial>
    <mass value="0.033333" />
    <origin xyz="0.0 0.0 0.0029166" rpy="0 0 0" />
    <inertia ixx="0.0000103029" ixy="0.0" ixz="0.0" iyy="0.0000103029" iyz="0.0" izz="0.0000204167" />
  </inertial>
      <visual>
      <geometry>
        <cylinder length="0.00583333" radius="0.035"/>
      </geometry>
  </visual>
     <collision>
    <origin xyz="0 0 0" rpy="0 0 0"/>
    <geometry>
      <cylinder length="0.00583333" radius="0.035"/>
    </geometry>
  </collision> 
</link>
<link name="opto_link_5">
  <inertial>
    <mass value="0.033333" />
    <origin xyz="0.0 0.0 0.0029166" rpy="0 0 0" />
    <inertia ixx="0.0000103029" ixy="0.0" ixz="0.0" iyy="0.0000103029" iyz="0.0" izz="0.0000204167" />
  </inertial>
    <visual>
      <geometry>
        <cylinder length="0.00583333" radius="0.035"/>
      </geometry>
  </visual>
     <collision>
    <origin xyz="0 0 0" rpy="0 0 0"/>
    <geometry>
      <cylinder length="0.00583333" radius="0.035"/>
    </geometry>
  </collision> 
</link>
<link name="opto_link_6">
  <inertial>
    <mass value="0.033333" />
    <origin xyz="0.0 0.0 0.0029166" rpy="0 0 0" />
    <inertia ixx="0.0000103029" ixy="0.0" ixz="0.0" iyy="0.0000103029" iyz="0.0" izz="0.0000204167" />
  </inertial>
      <visual>
      <geometry>
        <cylinder length="0.00583333" radius="0.035"/>
      </geometry>
  </visual>
   <collision>
    <origin xyz="0 0 0" rpy="0 0 0"/>
    <geometry>
      <cylinder length="0.00583333" radius="0.035"/>
    </geometry>
  </collision> 
</link>
<link name="svh_hand">
  <inertial>
    <mass value="1.3" />
    <origin xyz="0.0 0.0 0.01" rpy="0 0 0" />
    <inertia ixx="0.0077" ixy="0.0" ixz="0.0" iyy="0.0077" iyz="0.0" izz="0.0077"/>
  </inertial>
  <visual>
    <origin xyz="0 0 0" rpy="0 0 0"/>
    <geometry>
      <sphere radius="0.05" />
    </geometry>
  </visual>
  <collision>
    <origin xyz="0 0 0" rpy="0 0 0"/>
    <geometry>
      <sphere radius="0.05" />
    </geometry>
  </collision>
</link>      

    <joint name="joint1" type="revolute">
      <safety_controller k_position="100.0" k_velocity="40.0" soft_lower_limit="-2.8973" soft_upper_limit="2.8973"/>
      <origin rpy="0 0 0" xyz="0 0 0.333"/>
      <parent link="link0"/>
      <child link="link1"/>
      <axis xyz="0 0 1"/>
      <limit effort="87" lower="-2.8973" upper="2.8973" velocity="2.1750"/>
    </joint>
    <joint name="joint2" type="revolute">
      <safety_controller k_position="100.0" k_velocity="40.0" soft_lower_limit="-1.7628" soft_upper_limit="1.7628"/>
      <origin rpy="-1.57079632679 0 0" xyz="0 0 0"/>
      <parent link="link1"/>
      <child link="link2"/>
      <axis xyz="0 0 1"/>
      <calibration falling="-45.0" />
      <limit effort="87" lower="-1.7628" upper="1.7628" velocity="2.1750"/>
    </joint>
    <joint name="joint3" type="revolute">
      <safety_controller k_position="100.0" k_velocity="40.0" soft_lower_limit="-2.8973" soft_upper_limit="2.8973"/>
      <origin rpy="1.57079632679 0 0" xyz="0 -0.316 0"/>
      <parent link="link2"/>
      <child link="link3"/>
      <axis xyz="0 0 1"/>
      <limit effort="87" lower="-2.8973" upper="2.8973" velocity="2.1750"/>
    </joint>
    <joint name="joint4" type="revolute">
      <safety_controller k_position="100.0" k_velocity="40.0" soft_lower_limit="-3.0718" soft_upper_limit="-0.0698"/>
      <origin rpy="1.57079632679 0 0" xyz="0.0825 0 0"/>
      <parent link="link3"/>
      <child link="link4"/>
      <axis xyz="0 0 1"/>
      <calibration falling="-125.0" />
      <limit effort="87" lower="-3.0718" upper="-0.0698" velocity="2.1750"/>
    </joint>
    <joint name="joint5" type="revolute">
      <safety_controller k_position="100.0" k_velocity="40.0" soft_lower_limit="-2.8973" soft_upper_limit="2.8973"/>
      <origin rpy="-1.57079632679 0 0" xyz="-0.0825 0.384 0"/>
      <parent link="link4"/>
      <child link="link5"/>
      <axis xyz="0 0 1"/>
      <limit effort="12" lower="-2.8973" upper="2.8973" velocity="2.6100"/>
    </joint>
    <joint name="joint6" type="revolute">
      <safety_controller k_position="100.0" k_velocity="40.0" soft_lower_limit="-0.0175" soft_upper_limit="3.7525"/>
      <origin rpy="1.57079632679 0 0" xyz="0 0 0"/>
      <parent link="link5"/>
      <child link="link6"/>
      <axis xyz="0 0 1"/>
      <calibration falling="80.0" />
      <limit effort="12" lower="-0.0175" upper="3.7525" velocity="2.6100"/>
    </joint>
    <joint name="joint7" type="revolute">
      <safety_controller k_position="100.0" k_velocity="40.0" soft_lower_limit="-2.8973" soft_upper_limit="2.8973"/>
      <origin rpy="1.57079632679 0 0" xyz="0.088 0 0"/>
      <parent link="link6"/>
      <child link="link7"/>
      <axis xyz="0 0 1"/>
      <limit effort="12" lower="-2.8973" upper="2.8973" velocity="2.6100"/>
    </joint>
    <joint name = "flange" type="fixed">
      <origin rpy="0 0 0" xyz="0 0 0.107"/>
      <parent link="link7"/>
      <child link="opto_link_1"/>
     </joint> 
    <joint name="opto_joint_1" type="prismatic">
      <parent link="opto_link_1"/>
      <child link="opto_link_2"/>
      <axis xyz="1 0 0"/>
      <limit effort="12" lower="-0.0175" upper="3.7525" velocity="2.6100"/>
    </joint>
    <joint name="opto_joint_2" type="prismatic">
      <parent link="opto_link_2"/>
      <child link="opto_link_3"/>
      <axis xyz="0 1 0"/>
      <limit effort="12" lower="-0.0175" upper="3.7525" velocity="2.6100"/>
    </joint>
    <joint name="opto_joint_3" type="prismatic">
      <parent link="opto_link_3"/>
      <child link="opto_link_4"/>
      <axis xyz="0 0 1"/>
      <limit effort="12" lower="-0.0175" upper="3.7525" velocity="2.6100"/>
    </joint>
    <joint name="opto_joint_4" type="revolute">
      <parent link="opto_link_4"/>
      <child link="opto_link_5"/>
      <axis xyz="1 0 0"/>
      <limit effort="12" lower="-0.0175" upper="3.7525" velocity="2.6100"/>
    </joint>
    <joint name="opto_joint_5" type="revolute">
      <parent link="opto_link_5"/>
      <child link="opto_link_6"/>
      <axis xyz="0 1 0"/>
      <limit effort="12" lower="-0.0175" upper="3.7525" velocity="2.6100"/>
    </joint>
    <joint name="opto_joint_6" type="revolute">
      <parent link="opto_link_6"/>
      <child link="svh_hand"/>
      <axis xyz="0 0 1"/>
      <limit effort="12" lower="-0.0175" upper="3.7525" velocity="2.6100"/>
    </joint>
  <!-- </xacro:macro> -->
</robot>
